<sdf version='1.7'>
  <world name='default'>
    <plugin name='welcome_message' filename='libwelcome_message.so'/>
    <light name='sun' type='directional'>
      <cast_shadows>1</cast_shadows>
      <pose>0 0 10 0 -0 0</pose>
      <diffuse>0.8 0.8 0.8 1</diffuse>
      <specular>0.2 0.2 0.2 1</specular>
      <attenuation>
        <range>1000</range>
        <constant>0.9</constant>
        <linear>0.01</linear>
        <quadratic>0.001</quadratic>
      </attenuation>
      <direction>-0.5 0.1 -0.9</direction>
      <spot>
        <inner_angle>0</inner_angle>
        <outer_angle>0</outer_angle>
        <falloff>0</falloff>
      </spot>
    </light>
    <model name='ground_plane'>
      <static>1</static>
      <link name='link'>
        <collision name='collision'>
          <geometry>
            <plane>
              <normal>0 0 1</normal>
              <size>100 100</size>
            </plane>
          </geometry>
          <surface>
            <contact>
              <collide_bitmask>65535</collide_bitmask>
              <ode/>
            </contact>
            <friction>
              <ode>
                <mu>100</mu>
                <mu2>50</mu2>
              </ode>
              <torsional>
                <ode/>
              </torsional>
            </friction>
            <bounce/>
          </surface>
          <max_contacts>10</max_contacts>
        </collision>
        <visual name='visual'>
          <cast_shadows>0</cast_shadows>
          <geometry>
            <plane>
              <normal>0 0 1</normal>
              <size>100 100</size>
            </plane>
          </geometry>
          <material>
            <script>
              <uri>file://media/materials/scripts/gazebo.material</uri>
              <name>Gazebo/Grey</name>
            </script>
          </material>
        </visual>
        <self_collide>0</self_collide>
        <enable_wind>0</enable_wind>
        <kinematic>0</kinematic>
      </link>
    </model>
    <gravity>0 0 -9.8</gravity>
    <magnetic_field>6e-06 2.3e-05 -4.2e-05</magnetic_field>
    <atmosphere type='adiabatic'/>
    <physics type='ode'>
      <max_step_size>0.001</max_step_size>
      <real_time_factor>1</real_time_factor>
      <real_time_update_rate>1000</real_time_update_rate>
    </physics>
    <scene>
      <ambient>0.4 0.4 0.4 1</ambient>
      <background>0.7 0.7 0.7 1</background>
      <shadows>1</shadows>
    </scene>
    <wind/>
    <spherical_coordinates>
      <surface_model>EARTH_WGS84</surface_model>
      <latitude_deg>0</latitude_deg>
      <longitude_deg>0</longitude_deg>
      <elevation>0</elevation>
      <heading_deg>0</heading_deg>
    </spherical_coordinates>
    <state world_name='default'>
      <sim_time>235 698000000</sim_time>
      <real_time>35 687555072</real_time>
      <wall_time>1721652701 968060423</wall_time>
      <iterations>35580</iterations>
      <model name='MyBuilding'>
        <pose>-0.042925 1.84585 0 0 -0 0</pose>
        <scale>1 1 1</scale>
        <link name='Wall_1'>
          <pose>-0.042925 -2.07915 0 0 -0 0</pose>
          <velocity>0 0 0 0 -0 0</velocity>
          <acceleration>0 0 0 0 -0 0</acceleration>
          <wrench>0 0 0 0 -0 0</wrench>
        </link>
        <link name='Wall_11'>
          <pose>-3.02135 1.1995 0 0 0 -1.5708</pose>
          <velocity>0 0 0 0 -0 0</velocity>
          <acceleration>0 0 0 0 -0 0</acceleration>
          <wrench>0 0 0 0 -0 0</wrench>
        </link>
        <link name='Wall_2'>
          <pose>6.75708 1.84586 0 0 -0 1.5708</pose>
          <velocity>0 0 0 0 -0 0</velocity>
          <acceleration>0 0 0 0 -0 0</acceleration>
          <wrench>0 0 0 0 -0 0</wrench>
        </link>
        <link name='Wall_3'>
          <pose>-0.042925 5.77086 0 0 -0 3.14159</pose>
          <velocity>0 0 0 0 -0 0</velocity>
          <acceleration>0 0 0 0 -0 0</acceleration>
          <wrench>0 0 0 0 -0 0</wrench>
        </link>
        <link name='Wall_6'>
          <pose>-6.84293 1.84586 0 0 0 -1.5708</pose>
          <velocity>0 0 0 0 -0 0</velocity>
          <acceleration>0 0 0 0 -0 0</acceleration>
          <wrench>0 0 0 0 -0 0</wrench>
        </link>
        <link name='Wall_8'>
          <pose>-1.0301 4.21221 0 0 0 -1.5708</pose>
          <velocity>0 0 0 0 -0 0</velocity>
          <acceleration>0 0 0 0 -0 0</acceleration>
          <wrench>0 0 0 0 -0 0</wrench>
        </link>
        <link name='Wall_9'>
          <pose>-2.95511 2.66222 0 0 -0 3.14159</pose>
          <velocity>0 0 0 0 -0 0</velocity>
          <acceleration>0 0 0 0 -0 0</acceleration>
          <wrench>0 0 0 0 -0 0</wrench>
        </link>
      </model>
      <model name='ground_plane'>
        <pose>0 0 0 0 -0 0</pose>
        <scale>1 1 1</scale>
        <link name='link'>
          <pose>0 0 0 0 -0 0</pose>
          <velocity>0 0 0 0 -0 0</velocity>
          <acceleration>0 0 0 0 -0 0</acceleration>
          <wrench>0 0 0 0 -0 0</wrench>
        </link>
      </model>
      <model name='mobilerobot'>
        <pose>0.004358 0.012015 0.005043 2e-06 -0.016588 0.061773</pose>
        <scale>1 1 1</scale>
        <link name='link_0'>
          <pose>0.001047 0.01181 0.205015 2e-06 -0.016588 0.061773</pose>
          <velocity>-0.000248 -0.000139 0.003701 0.002356 -0.013982 0.00053</velocity>
          <acceleration>-0.345067 -1.20302 6.74179 2.29137 1.49425 0.342608</acceleration>
          <wrench>-0.345067 -1.20302 6.74179 0 -0 0</wrench>
        </link>
        <link name='link_1'>
          <pose>-0.279809 -0.306295 0.200039 1.57 0.119651 0.061665</pose>
          <velocity>-1.4e-05 -0.000299 -0.000978 0.001411 0.000812 0.000521</velocity>
          <acceleration>-0.104045 -1.33503 -4.4022 0.308975 0.407913 0.279145</acceleration>
          <wrench>-0.104045 -1.33503 -4.4022 0 -0 0</wrench>
        </link>
        <link name='link_1_clone'>
          <pose>-0.316869 0.292878 0.20004 1.56997 -0.284038 0.061992</pose>
          <velocity>-0.000307 -0.000312 -7.3e-05 0.001569 -0.001658 0.000513</velocity>
          <acceleration>-0.251137 -1.28185 -0.333621 -2.62936 -1.52827 -2.89345</acceleration>
          <wrench>-0.251137 -1.28185 -0.333621 0 -0 0</wrench>
        </link>
        <link name='link_2'>
          <pose>0.301427 0.030389 0.15 -0.034573 0.601204 -0.036052</pose>
          <velocity>0.000492 0.000175 0.007944 -0.001167 0.003276 0</velocity>
          <acceleration>1.26519 -0.584742 15.8889 -0.524617 1.163 0</acceleration>
          <wrench>1.26519 -0.584742 15.8889 0 -0 0</wrench>
        </link>
      </model>
      <model name='mobilerobot2'>
        <pose>2.29445 4.87785 0.142749 0 1e-05 0.101298</pose>
        <scale>1 1 1</scale>
        <model name='husky'>
          <pose>2.29445 4.87785 0.142749 0 1e-05 0.101298</pose>
          <scale>1 1 1</scale>
          <link name='back_left_wheel'>
            <pose>2.0109 5.13597 0.177751 3.14158 0.413042 -3.0403</pose>
            <velocity>-0.001739 -0.001011 -0.003306 -0.001337 -0.011506 0.001069</velocity>
            <acceleration>0.077411 -0.270194 -9.72995 0.849761 -0.552272 -2.23272</acceleration>
            <wrench>0.204032 -0.712149 -25.6452 0 -0 0</wrench>
          </link>
          <link name='back_right_wheel'>
            <pose>2.06863 4.56795 0.177751 3.14158 -0.090255 -3.04029</pose>
            <velocity>-0.000851 -0.000894 -0.00351 -0.002074 -0.005736 0.001726</velocity>
            <acceleration>-0.027683 -0.227578 -9.88305 0.513253 -0.586477 0.375361</acceleration>
            <wrench>-0.072965 -0.599828 -26.0488 0 -0 0</wrench>
          </link>
          <link name='base_link'>
            <pose>2.29445 4.87785 0.142749 0 1e-05 0.101298</pose>
            <velocity>-0.001407 -0.000394 -0.003809 9.3e-05 0.001599 0.001593</velocity>
            <acceleration>-0.000856 0.020809 -9.79933 0.063927 0.010665 -0.126344</acceleration>
            <wrench>-0.028964 0.704483 -331.756 0 -0 0</wrench>
          </link>
          <link name='front_left_wheel'>
            <pose>2.52027 5.18775 0.177746 -3.7e-05 -1.50468 0.101334</pose>
            <velocity>-0.001845 2.8e-05 -0.004122 0.001881 -0.009904 0.001628</velocity>
            <acceleration>0.036701 0.129565 -9.74136 0.74746 0.075973 -0.056178</acceleration>
            <wrench>0.096732 0.341493 -25.6753 0 -0 0</wrench>
          </link>
          <link name='front_right_wheel'>
            <pose>2.57801 4.61972 0.177746 -2.1e-05 -1.44675 0.101319</pose>
            <velocity>-0.00096 0.000109 -0.004305 0.001355 -0.004265 0.001595</velocity>
            <acceleration>-0.07544 0.100922 -9.8543 0.798404 0.081152 -0.138297</acceleration>
            <wrench>-0.198836 0.266001 -25.973 0 -0 0</wrench>
          </link>
        </model>
      </model>
      <model name='my_ball_0'>
        <pose>2.47418 -3.50185 0.1 0 -0 0</pose>
        <scale>1 1 1</scale>
        <link name='link_0'>
          <pose>2.47418 -3.50185 0.1 0 -0 0</pose>
          <velocity>0 0 0 0 -0 0</velocity>
          <acceleration>0 0 0 0 -0 0</acceleration>
          <wrench>0 0 0 0 -0 0</wrench>
        </link>
      </model>
      <light name='sun'>
        <pose>0 0 10 0 -0 0</pose>
      </light>
    </state>
    <model name='mobilerobot'>
      <link name='link_0'>
        <inertial>
          <mass>1</mass>
          <inertia>
            <ixx>0.166667</ixx>
            <ixy>0</ixy>
            <ixz>0</ixz>
            <iyy>0.166667</iyy>
            <iyz>0</iyz>
            <izz>0.166667</izz>
          </inertia>
          <pose>0 0 0 0 -0 0</pose>
        </inertial>
        <pose>0 0 0.2 0 -0 0</pose>
        <gravity>1</gravity>
        <self_collide>0</self_collide>
        <kinematic>0</kinematic>
        <enable_wind>0</enable_wind>
        <visual name='visual'>
          <pose>0 0 0 0 -0 0</pose>
          <geometry>
            <box>
              <size>1 0.5 0.1</size>
            </box>
          </geometry>
          <material>
            <lighting>1</lighting>
            <script>
              <uri>file://media/materials/scripts/gazebo.material</uri>
              <name>Gazebo/Grey</name>
            </script>
            <shader type='pixel'>
              <normal_map>__default__</normal_map>
            </shader>
            <ambient>0.3 0.3 0.3 1</ambient>
            <diffuse>0.7 0.7 0.7 1</diffuse>
            <specular>0.01 0.01 0.01 1</specular>
            <emissive>0 0 0 1</emissive>
          </material>
          <transparency>0</transparency>
          <cast_shadows>1</cast_shadows>
        </visual>
        <collision name='collision'>
          <laser_retro>0</laser_retro>
          <max_contacts>10</max_contacts>
          <pose>0 0 0 0 -0 0</pose>
          <geometry>
            <box>
              <size>1 0.5 0.1</size>
            </box>
          </geometry>
          <surface>
            <friction>
              <ode>
                <mu>1</mu>
                <mu2>1</mu2>
                <fdir1>0 0 0</fdir1>
                <slip1>0</slip1>
                <slip2>0</slip2>
              </ode>
              <torsional>
                <coefficient>1</coefficient>
                <patch_radius>0</patch_radius>
                <surface_radius>0</surface_radius>
                <use_patch_radius>1</use_patch_radius>
                <ode>
                  <slip>0</slip>
                </ode>
              </torsional>
            </friction>
            <bounce>
              <restitution_coefficient>0</restitution_coefficient>
              <threshold>1e+06</threshold>
            </bounce>
            <contact>
              <collide_without_contact>0</collide_without_contact>
              <collide_without_contact_bitmask>1</collide_without_contact_bitmask>
              <collide_bitmask>1</collide_bitmask>
              <ode>
                <soft_cfm>0</soft_cfm>
                <soft_erp>0.2</soft_erp>
                <kp>1e+13</kp>
                <kd>1</kd>
                <max_vel>0.01</max_vel>
                <min_depth>0</min_depth>
              </ode>
              <bullet>
                <split_impulse>1</split_impulse>
                <split_impulse_penetration_threshold>-0.01</split_impulse_penetration_threshold>
                <soft_cfm>0</soft_cfm>
                <soft_erp>0.2</soft_erp>
                <kp>1e+13</kp>
                <kd>1</kd>
              </bullet>
            </contact>
          </surface>
        </collision>
      </link>
      <link name='link_1'>
        <inertial>
          <mass>1</mass>
          <inertia>
            <ixx>0.145833</ixx>
            <ixy>0</ixy>
            <ixz>0</ixz>
            <iyy>0.145833</iyy>
            <iyz>0</iyz>
            <izz>0.125</izz>
          </inertia>
          <pose>0 0 0 0 -0 0</pose>
        </inertial>
        <pose>-0.3 -0.300159 0.2 1.57 -0 0</pose>
        <gravity>1</gravity>
        <self_collide>0</self_collide>
        <kinematic>0</kinematic>
        <enable_wind>0</enable_wind>
        <visual name='visual'>
          <pose>0 0 0 0 -0 0</pose>
          <geometry>
            <cylinder>
              <radius>0.2</radius>
              <length>0.1</length>
            </cylinder>
          </geometry>
          <material>
            <lighting>1</lighting>
            <script>
              <uri>file://media/materials/scripts/gazebo.material</uri>
              <name>Gazebo/Grey</name>
            </script>
            <shader type='pixel'>
              <normal_map>__default__</normal_map>
            </shader>
            <ambient>0.3 0.3 0.3 1</ambient>
            <diffuse>0.7 0.7 0.7 1</diffuse>
            <specular>0.01 0.01 0.01 1</specular>
            <emissive>0 0 0 1</emissive>
          </material>
          <transparency>0</transparency>
          <cast_shadows>1</cast_shadows>
        </visual>
        <collision name='collision'>
          <laser_retro>0</laser_retro>
          <max_contacts>10</max_contacts>
          <pose>0 0 0 0 -0 0</pose>
          <geometry>
            <cylinder>
              <radius>0.2</radius>
              <length>0.1</length>
            </cylinder>
          </geometry>
          <surface>
            <friction>
              <ode>
                <mu>1</mu>
                <mu2>1</mu2>
                <fdir1>0 0 0</fdir1>
                <slip1>0</slip1>
                <slip2>0</slip2>
              </ode>
              <torsional>
                <coefficient>1</coefficient>
                <patch_radius>0</patch_radius>
                <surface_radius>0</surface_radius>
                <use_patch_radius>1</use_patch_radius>
                <ode>
                  <slip>0</slip>
                </ode>
              </torsional>
            </friction>
            <bounce>
              <restitution_coefficient>0</restitution_coefficient>
              <threshold>1e+06</threshold>
            </bounce>
            <contact>
              <collide_without_contact>0</collide_without_contact>
              <collide_without_contact_bitmask>1</collide_without_contact_bitmask>
              <collide_bitmask>1</collide_bitmask>
              <ode>
                <soft_cfm>0</soft_cfm>
                <soft_erp>0.2</soft_erp>
                <kp>1e+13</kp>
                <kd>1</kd>
                <max_vel>0.01</max_vel>
                <min_depth>0</min_depth>
              </ode>
              <bullet>
                <split_impulse>1</split_impulse>
                <split_impulse_penetration_threshold>-0.01</split_impulse_penetration_threshold>
                <soft_cfm>0</soft_cfm>
                <soft_erp>0.2</soft_erp>
                <kp>1e+13</kp>
                <kd>1</kd>
              </bullet>
            </contact>
          </surface>
        </collision>
      </link>
      <link name='link_1_clone'>
        <inertial>
          <mass>1</mass>
          <inertia>
            <ixx>0.145833</ixx>
            <ixy>0</ixy>
            <ixz>0</ixz>
            <iyy>0.145833</iyy>
            <iyz>0</iyz>
            <izz>0.125</izz>
          </inertia>
          <pose>0 0 0 0 -0 0</pose>
        </inertial>
        <pose>-0.3 0.300159 0.2 1.57 -0 0</pose>
        <gravity>1</gravity>
        <self_collide>0</self_collide>
        <kinematic>0</kinematic>
        <enable_wind>0</enable_wind>
        <visual name='visual'>
          <pose>0 0 0 0 -0 0</pose>
          <geometry>
            <cylinder>
              <radius>0.2</radius>
              <length>0.1</length>
            </cylinder>
          </geometry>
          <material>
            <lighting>1</lighting>
            <script>
              <uri>file://media/materials/scripts/gazebo.material</uri>
              <name>Gazebo/Grey</name>
            </script>
            <shader type='pixel'>
              <normal_map>__default__</normal_map>
            </shader>
            <ambient>0.3 0.3 0.3 1</ambient>
            <diffuse>0.7 0.7 0.7 1</diffuse>
            <specular>0.01 0.01 0.01 1</specular>
            <emissive>0 0 0 1</emissive>
          </material>
          <transparency>0</transparency>
          <cast_shadows>1</cast_shadows>
        </visual>
        <collision name='collision'>
          <laser_retro>0</laser_retro>
          <max_contacts>10</max_contacts>
          <pose>0 0 0 0 -0 0</pose>
          <geometry>
            <cylinder>
              <radius>0.2</radius>
              <length>0.1</length>
            </cylinder>
          </geometry>
          <surface>
            <friction>
              <ode>
                <mu>1</mu>
                <mu2>1</mu2>
                <fdir1>0 0 0</fdir1>
                <slip1>0</slip1>
                <slip2>0</slip2>
              </ode>
              <torsional>
                <coefficient>1</coefficient>
                <patch_radius>0</patch_radius>
                <surface_radius>0</surface_radius>
                <use_patch_radius>1</use_patch_radius>
                <ode>
                  <slip>0</slip>
                </ode>
              </torsional>
            </friction>
            <bounce>
              <restitution_coefficient>0</restitution_coefficient>
              <threshold>1e+06</threshold>
            </bounce>
            <contact>
              <collide_without_contact>0</collide_without_contact>
              <collide_without_contact_bitmask>1</collide_without_contact_bitmask>
              <collide_bitmask>1</collide_bitmask>
              <ode>
                <soft_cfm>0</soft_cfm>
                <soft_erp>0.2</soft_erp>
                <kp>1e+13</kp>
                <kd>1</kd>
                <max_vel>0.01</max_vel>
                <min_depth>0</min_depth>
              </ode>
              <bullet>
                <split_impulse>1</split_impulse>
                <split_impulse_penetration_threshold>-0.01</split_impulse_penetration_threshold>
                <soft_cfm>0</soft_cfm>
                <soft_erp>0.2</soft_erp>
                <kp>1e+13</kp>
                <kd>1</kd>
              </bullet>
            </contact>
          </surface>
        </collision>
      </link>
      <link name='link_2'>
        <inertial>
          <mass>1</mass>
          <inertia>
            <ixx>0.1</ixx>
            <ixy>0</ixy>
            <ixz>0</ixz>
            <iyy>0.1</iyy>
            <iyz>0</iyz>
            <izz>0.1</izz>
          </inertia>
          <pose>0 0 0 0 -0 0</pose>
        </inertial>
        <pose>0.3 0 0.14 0 -0 0</pose>
        <gravity>1</gravity>
        <self_collide>0</self_collide>
        <kinematic>0</kinematic>
        <enable_wind>0</enable_wind>
        <visual name='visual'>
          <pose>0 0 0 0 -0 0</pose>
          <geometry>
            <sphere>
              <radius>0.15</radius>
            </sphere>
          </geometry>
          <material>
            <lighting>1</lighting>
            <script>
              <uri>file://media/materials/scripts/gazebo.material</uri>
              <name>Gazebo/Grey</name>
            </script>
            <shader type='pixel'>
              <normal_map>__default__</normal_map>
            </shader>
            <ambient>0.3 0.3 0.3 1</ambient>
            <diffuse>0.7 0.7 0.7 1</diffuse>
            <specular>0.01 0.01 0.01 1</specular>
            <emissive>0 0 0 1</emissive>
          </material>
          <transparency>0</transparency>
          <cast_shadows>1</cast_shadows>
        </visual>
        <collision name='collision'>
          <laser_retro>0</laser_retro>
          <max_contacts>10</max_contacts>
          <pose>0 0 0 0 -0 0</pose>
          <geometry>
            <sphere>
              <radius>0.15</radius>
            </sphere>
          </geometry>
          <surface>
            <friction>
              <ode>
                <mu>1</mu>
                <mu2>1</mu2>
                <fdir1>0 0 0</fdir1>
                <slip1>0</slip1>
                <slip2>0</slip2>
              </ode>
              <torsional>
                <coefficient>1</coefficient>
                <patch_radius>0</patch_radius>
                <surface_radius>0</surface_radius>
                <use_patch_radius>1</use_patch_radius>
                <ode>
                  <slip>0</slip>
                </ode>
              </torsional>
            </friction>
            <bounce>
              <restitution_coefficient>0</restitution_coefficient>
              <threshold>1e+06</threshold>
            </bounce>
            <contact>
              <collide_without_contact>0</collide_without_contact>
              <collide_without_contact_bitmask>1</collide_without_contact_bitmask>
              <collide_bitmask>1</collide_bitmask>
              <ode>
                <soft_cfm>0</soft_cfm>
                <soft_erp>0.2</soft_erp>
                <kp>1e+13</kp>
                <kd>1</kd>
                <max_vel>0.01</max_vel>
                <min_depth>0</min_depth>
              </ode>
              <bullet>
                <split_impulse>1</split_impulse>
                <split_impulse_penetration_threshold>-0.01</split_impulse_penetration_threshold>
                <soft_cfm>0</soft_cfm>
                <soft_erp>0.2</soft_erp>
                <kp>1e+13</kp>
                <kd>1</kd>
              </bullet>
            </contact>
          </surface>
        </collision>
      </link>
      <joint name='link_0_JOINT_0' type='revolute'>
        <parent>link_0</parent>
        <child>link_1</child>
        <pose>0 0 0 0 -0 0</pose>
        <axis>
          <xyz>0 0 1</xyz>
          <limit>
            <lower>-1.79769e+308</lower>
            <upper>1.79769e+308</upper>
            <effort>-1</effort>
            <velocity>-1</velocity>
          </limit>
          <dynamics>
            <spring_reference>0</spring_reference>
            <spring_stiffness>0</spring_stiffness>
            <damping>0</damping>
            <friction>0</friction>
          </dynamics>
        </axis>
        <physics>
          <ode>
            <limit>
              <cfm>0</cfm>
              <erp>0.2</erp>
            </limit>
            <suspension>
              <cfm>0</cfm>
              <erp>0.2</erp>
            </suspension>
          </ode>
        </physics>
      </joint>
      <joint name='link_0_JOINT_1' type='revolute'>
        <parent>link_0</parent>
        <child>link_1_clone</child>
        <pose>0 0 0 0 -0 0</pose>
        <axis>
          <xyz>0 0 1</xyz>
          <limit>
            <lower>-1.79769e+308</lower>
            <upper>1.79769e+308</upper>
            <effort>-1</effort>
            <velocity>-1</velocity>
          </limit>
          <dynamics>
            <spring_reference>0</spring_reference>
            <spring_stiffness>0</spring_stiffness>
            <damping>0</damping>
            <friction>0</friction>
          </dynamics>
        </axis>
        <physics>
          <ode>
            <limit>
              <cfm>0</cfm>
              <erp>0.2</erp>
            </limit>
            <suspension>
              <cfm>0</cfm>
              <erp>0.2</erp>
            </suspension>
          </ode>
        </physics>
      </joint>
      <joint name='link_0_JOINT_2' type='ball'>
        <parent>link_0</parent>
        <child>link_2</child>
        <pose>0 0 0 0 -0 0</pose>
        <physics>
          <ode>
            <limit>
              <cfm>0</cfm>
              <erp>0.2</erp>
            </limit>
            <suspension>
              <cfm>0</cfm>
              <erp>0.2</erp>
            </suspension>
          </ode>
        </physics>
      </joint>
      <static>0</static>
      <allow_auto_disable>1</allow_auto_disable>
      <pose>0 0 0 0 -0 0</pose>
    </model>
    <model name='mobilerobot2'>
      <model name='husky'>
        <pose>3e-06 -3e-06 0 0 -0 0</pose>
        <link name='base_link'>
          <collision name='collision'>
            <pose>0 0 0.1 0 -0 0</pose>
            <geometry>
              <box>
                <size>1.0074 0.5709 0.2675</size>
              </box>
            </geometry>
            <max_contacts>10</max_contacts>
            <surface>
              <contact>
                <ode/>
              </contact>
              <bounce/>
              <friction>
                <torsional>
                  <ode/>
                </torsional>
                <ode/>
              </friction>
            </surface>
          </collision>
          <inertial>
            <mass>33.855</mass>
            <pose>-0.085613 -0.00084 0.238145 0 -0 0</pose>
            <inertia>
              <ixx>2.2343</ixx>
              <ixy>-0.023642</ixy>
              <ixz>0.275174</ixz>
              <iyy>3.42518</iyy>
              <iyz>0.00239624</iyz>
              <izz>2.1241</izz>
            </inertia>
          </inertial>
          <visual name='base'>
            <pose>0 0 0 0 -0 0</pose>
            <geometry>
              <mesh>
                <uri>model://husky/meshes/base_link.stl</uri>
              </mesh>
            </geometry>
            <material>
              <script>
                <name>Gazebo/FlatBlack</name>
                <uri>__default__</uri>
              </script>
            </material>
          </visual>
          <visual name='top_plate'>
            <pose>0 0 0 0 -0 0</pose>
            <geometry>
              <mesh>
                <uri>model://husky/meshes/top_plate.stl</uri>
              </mesh>
            </geometry>
            <material>
              <script>
                <name>Gazebo/Yellow</name>
                <uri>__default__</uri>
              </script>
            </material>
          </visual>
          <visual name='front_bumper'>
            <pose>0.47 0 0.091 0 -0 0</pose>
            <geometry>
              <mesh>
                <uri>model://husky/meshes/bumper.stl</uri>
              </mesh>
            </geometry>
            <material>
              <script>
                <name>Gazebo/FlatBlack</name>
                <uri>__default__</uri>
              </script>
            </material>
          </visual>
          <visual name='rear_bumper'>
            <pose>-0.47 0 0.091 0 -0 3.141</pose>
            <geometry>
              <mesh>
                <uri>model://husky/meshes/bumper.stl</uri>
              </mesh>
            </geometry>
            <material>
              <script>
                <name>Gazebo/FlatBlack</name>
                <uri>__default__</uri>
              </script>
            </material>
          </visual>
          <visual name='user_rail'>
            <pose>0.272 0 0.245 0 -0 0</pose>
            <geometry>
              <mesh>
                <uri>model://husky/meshes/user_rail.stl</uri>
              </mesh>
            </geometry>
            <material>
              <script>
                <name>Gazebo/Grey</name>
                <uri>__default__</uri>
              </script>
            </material>
          </visual>
          <self_collide>0</self_collide>
          <enable_wind>0</enable_wind>
          <kinematic>0</kinematic>
        </link>
        <link name='back_left_wheel'>
          <pose>-0.256 0.285475 0.035 0 -0 0</pose>
          <inertial>
            <mass>2.6357</mass>
            <pose>0 0 0 0 -0 0</pose>
            <inertia>
              <ixx>0.0246688</ixx>
              <ixy>0</ixy>
              <ixz>0</ixz>
              <iyy>0.0246688</iyy>
              <iyz>0</iyz>
              <izz>0.0441058</izz>
            </inertia>
          </inertial>
          <collision name='back_left_wheel_collision'>
            <pose>0 0 0 -1.5707 0 0</pose>
            <geometry>
              <cylinder>
                <radius>0.17775</radius>
                <length>0.1143</length>
              </cylinder>
            </geometry>
            <surface>
              <friction>
                <ode>
                  <mu>100000</mu>
                  <mu2>100000</mu2>
                  <slip1>0</slip1>
                  <slip2>0</slip2>
                </ode>
                <torsional>
                  <ode/>
                </torsional>
              </friction>
              <contact>
                <ode/>
              </contact>
              <bounce/>
            </surface>
            <max_contacts>10</max_contacts>
          </collision>
          <visual name='back_left_wheel'>
            <pose>0 0 0 -3.14159 0 0</pose>
            <geometry>
              <mesh>
                <uri>model://husky/meshes/wheel.stl</uri>
              </mesh>
            </geometry>
            <material>
              <script>
                <name>Gazebo/Grey</name>
                <uri>__default__</uri>
              </script>
            </material>
          </visual>
          <self_collide>0</self_collide>
          <enable_wind>0</enable_wind>
          <kinematic>0</kinematic>
        </link>
        <joint name='back_left_joint' type='revolute'>
          <parent>base_link</parent>
          <child>back_left_wheel</child>
          <axis>
            <xyz expressed_in='__model__'>0 1 0</xyz>
            <limit>
              <lower>-1e+16</lower>
              <upper>1e+16</upper>
            </limit>
            <dynamics>
              <spring_reference>0</spring_reference>
              <spring_stiffness>0</spring_stiffness>
            </dynamics>
          </axis>
          <physics>
            <ode>
              <limit>
                <cfm>0</cfm>
                <erp>0.9</erp>
              </limit>
            </ode>
          </physics>
        </joint>
        <link name='back_right_wheel'>
          <pose>-0.256 -0.285475 0.035 0 -0 0</pose>
          <inertial>
            <mass>2.6357</mass>
            <pose>0 0 0 0 -0 0</pose>
            <inertia>
              <ixx>0.0246688</ixx>
              <ixy>0</ixy>
              <ixz>0</ixz>
              <iyy>0.0246688</iyy>
              <iyz>0</iyz>
              <izz>0.0441058</izz>
            </inertia>
          </inertial>
          <collision name='back_right_wheel_collision'>
            <pose>0 0 0 -1.5707 0 0</pose>
            <geometry>
              <cylinder>
                <radius>0.17775</radius>
                <length>0.1143</length>
              </cylinder>
            </geometry>
            <surface>
              <friction>
                <ode>
                  <mu>100000</mu>
                  <mu2>100000</mu2>
                  <slip1>0</slip1>
                  <slip2>0</slip2>
                </ode>
                <torsional>
                  <ode/>
                </torsional>
              </friction>
              <contact>
                <ode/>
              </contact>
              <bounce/>
            </surface>
            <max_contacts>10</max_contacts>
          </collision>
          <visual name='back_right_wheel'>
            <pose>0 0 0 -3.14159 0 0</pose>
            <geometry>
              <mesh>
                <uri>model://husky/meshes/wheel.stl</uri>
              </mesh>
            </geometry>
            <material>
              <script>
                <name>Gazebo/Grey</name>
                <uri>__default__</uri>
              </script>
            </material>
          </visual>
          <self_collide>0</self_collide>
          <enable_wind>0</enable_wind>
          <kinematic>0</kinematic>
        </link>
        <joint name='back_right_joint' type='revolute'>
          <parent>base_link</parent>
          <child>back_right_wheel</child>
          <axis>
            <xyz expressed_in='__model__'>0 1 0</xyz>
            <limit>
              <lower>-1e+16</lower>
              <upper>1e+16</upper>
            </limit>
            <dynamics>
              <spring_reference>0</spring_reference>
              <spring_stiffness>0</spring_stiffness>
            </dynamics>
          </axis>
          <physics>
            <ode>
              <limit>
                <cfm>0</cfm>
                <erp>0.9</erp>
              </limit>
            </ode>
          </physics>
        </joint>
        <link name='front_left_wheel'>
          <pose>0.256 0.285475 0.035 0 -0 0</pose>
          <inertial>
            <mass>2.6357</mass>
            <pose>0 0 0 0 -0 0</pose>
            <inertia>
              <ixx>0.0246688</ixx>
              <ixy>0</ixy>
              <ixz>0</ixz>
              <iyy>0.0246688</iyy>
              <iyz>0</iyz>
              <izz>0.0441058</izz>
            </inertia>
          </inertial>
          <collision name='front_left_wheel_collision'>
            <pose>0 0 0 -1.5707 0 0</pose>
            <geometry>
              <cylinder>
                <radius>0.17775</radius>
                <length>0.1143</length>
              </cylinder>
            </geometry>
            <surface>
              <friction>
                <ode>
                  <mu>100000</mu>
                  <mu2>100000</mu2>
                  <slip1>0</slip1>
                  <slip2>0</slip2>
                </ode>
                <torsional>
                  <ode/>
                </torsional>
              </friction>
              <contact>
                <ode/>
              </contact>
              <bounce/>
            </surface>
            <max_contacts>10</max_contacts>
          </collision>
          <visual name='front_left_wheel'>
            <pose>0 0 0 -3.14159 0 0</pose>
            <geometry>
              <mesh>
                <uri>model://husky/meshes/wheel.stl</uri>
              </mesh>
            </geometry>
            <material>
              <script>
                <name>Gazebo/Grey</name>
                <uri>__default__</uri>
              </script>
            </material>
          </visual>
          <self_collide>0</self_collide>
          <enable_wind>0</enable_wind>
          <kinematic>0</kinematic>
        </link>
        <joint name='front_left_joint' type='revolute'>
          <parent>base_link</parent>
          <child>front_left_wheel</child>
          <axis>
            <xyz expressed_in='__model__'>0 1 0</xyz>
            <limit>
              <lower>-1e+16</lower>
              <upper>1e+16</upper>
            </limit>
            <dynamics>
              <spring_reference>0</spring_reference>
              <spring_stiffness>0</spring_stiffness>
            </dynamics>
          </axis>
          <physics>
            <ode>
              <limit>
                <cfm>0</cfm>
                <erp>0.9</erp>
              </limit>
            </ode>
          </physics>
        </joint>
        <link name='front_right_wheel'>
          <pose>0.256 -0.285475 0.035 0 -0 0</pose>
          <inertial>
            <mass>2.6357</mass>
            <pose>0 0 0 0 -0 0</pose>
            <inertia>
              <ixx>0.0246688</ixx>
              <ixy>0</ixy>
              <ixz>0</ixz>
              <iyy>0.0246688</iyy>
              <iyz>0</iyz>
              <izz>0.0441058</izz>
            </inertia>
          </inertial>
          <collision name='front_right_wheel_collision'>
            <pose>0 0 0 -1.5707 0 0</pose>
            <geometry>
              <cylinder>
                <radius>0.17775</radius>
                <length>0.1143</length>
              </cylinder>
            </geometry>
            <surface>
              <friction>
                <ode>
                  <mu>100000</mu>
                  <mu2>100000</mu2>
                  <slip1>0</slip1>
                  <slip2>0</slip2>
                </ode>
                <torsional>
                  <ode/>
                </torsional>
              </friction>
              <contact>
                <ode/>
              </contact>
              <bounce/>
            </surface>
            <max_contacts>10</max_contacts>
          </collision>
          <visual name='front_right_wheel'>
            <pose>0 0 0 -3.14159 0 0</pose>
            <geometry>
              <mesh>
                <uri>model://husky/meshes/wheel.stl</uri>
              </mesh>
            </geometry>
            <material>
              <script>
                <name>Gazebo/Grey</name>
                <uri>__default__</uri>
              </script>
            </material>
          </visual>
          <self_collide>0</self_collide>
          <enable_wind>0</enable_wind>
          <kinematic>0</kinematic>
        </link>
        <joint name='front_right_joint' type='revolute'>
          <parent>base_link</parent>
          <child>front_right_wheel</child>
          <axis>
            <xyz expressed_in='__model__'>0 1 0</xyz>
            <limit>
              <lower>-1e+16</lower>
              <upper>1e+16</upper>
            </limit>
            <dynamics>
              <spring_reference>0</spring_reference>
              <spring_stiffness>0</spring_stiffness>
            </dynamics>
          </axis>
          <physics>
            <ode>
              <limit>
                <cfm>0</cfm>
                <erp>0.9</erp>
              </limit>
            </ode>
          </physics>
        </joint>
        <plugin name='husky_diff_controller' filename='libhusky_gazebo_plugins.so'>
          <alwaysOn>1</alwaysOn>
          <updateRate>100.0</updateRate>
          <backLeftJoint>back_left_joint</backLeftJoint>
          <backRightJoint>back_right_joint</backRightJoint>
          <frontLeftJoint>front_left_joint</frontLeftJoint>
          <frontRightJoint>front_right_joint</frontRightJoint>
          <wheelSeparation>0.5709</wheelSeparation>
          <wheelDiameter>0.3555</wheelDiameter>
          <torque>35</torque>
        </plugin>
      </model>
      <static>0</static>
      <allow_auto_disable>1</allow_auto_disable>
      <pose>1.59649 4.80223 0.5 0 -0 0</pose>
    </model>
    <model name='MyBuilding'>
      <pose>-0.042925 -3.71148 0 0 -0 0</pose>
      <link name='Wall_1'>
        <pose>0 -3.925 0 0 -0 0</pose>
        <visual name='Wall_1_Visual_0'>
          <pose>-2.46166 0 1.25 0 -0 0</pose>
          <geometry>
            <box>
              <size>8.82667 0.15 2.5</size>
            </box>
          </geometry>
          <material>
            <script>
              <uri>file://media/materials/scripts/gazebo.material</uri>
              <name>Gazebo/Wood</name>
            </script>
            <ambient>1 1 1 1</ambient>
          </material>
          <meta>
            <layer>0</layer>
          </meta>
        </visual>
        <collision name='Wall_1_Collision_0'>
          <geometry>
            <box>
              <size>8.82667 0.15 2.5</size>
            </box>
          </geometry>
          <pose>-2.46166 0 1.25 0 -0 0</pose>
          <max_contacts>10</max_contacts>
          <surface>
            <contact>
              <ode/>
            </contact>
            <bounce/>
            <friction>
              <torsional>
                <ode/>
              </torsional>
              <ode/>
            </friction>
          </surface>
        </collision>
        <visual name='Wall_1_Visual_1'>
          <pose>4.41334 0 0.25 0 -0 0</pose>
          <geometry>
            <box>
              <size>4.92333 0.15 0.5</size>
            </box>
          </geometry>
          <material>
            <script>
              <uri>file://media/materials/scripts/gazebo.material</uri>
              <name>Gazebo/Wood</name>
            </script>
            <ambient>1 1 1 1</ambient>
          </material>
          <meta>
            <layer>0</layer>
          </meta>
        </visual>
        <collision name='Wall_1_Collision_1'>
          <geometry>
            <box>
              <size>4.92333 0.15 0.5</size>
            </box>
          </geometry>
          <pose>4.41334 0 0.25 0 -0 0</pose>
          <max_contacts>10</max_contacts>
          <surface>
            <contact>
              <ode/>
            </contact>
            <bounce/>
            <friction>
              <torsional>
                <ode/>
              </torsional>
              <ode/>
            </friction>
          </surface>
        </collision>
        <visual name='Wall_1_Visual_2'>
          <pose>4.81334 0 1.5 0 -0 0</pose>
          <geometry>
            <box>
              <size>4.12333 0.15 2</size>
            </box>
          </geometry>
          <material>
            <script>
              <uri>file://media/materials/scripts/gazebo.material</uri>
              <name>Gazebo/Wood</name>
            </script>
            <ambient>1 1 1 1</ambient>
          </material>
          <meta>
            <layer>0</layer>
          </meta>
        </visual>
        <collision name='Wall_1_Collision_2'>
          <geometry>
            <box>
              <size>4.12333 0.15 2</size>
            </box>
          </geometry>
          <pose>4.81334 0 1.5 0 -0 0</pose>
          <max_contacts>10</max_contacts>
          <surface>
            <contact>
              <ode/>
            </contact>
            <bounce/>
            <friction>
              <torsional>
                <ode/>
              </torsional>
              <ode/>
            </friction>
          </surface>
        </collision>
        <visual name='Wall_1_Visual_3'>
          <pose>2.35168 0 1.9 0 -0 0</pose>
          <geometry>
            <box>
              <size>0.8 0.15 1.2</size>
            </box>
          </geometry>
          <material>
            <script>
              <uri>file://media/materials/scripts/gazebo.material</uri>
              <name>Gazebo/Wood</name>
            </script>
            <ambient>1 1 1 1</ambient>
          </material>
          <meta>
            <layer>0</layer>
          </meta>
        </visual>
        <collision name='Wall_1_Collision_3'>
          <geometry>
            <box>
              <size>0.8 0.15 1.2</size>
            </box>
          </geometry>
          <pose>2.35168 0 1.9 0 -0 0</pose>
          <max_contacts>10</max_contacts>
          <surface>
            <contact>
              <ode/>
            </contact>
            <bounce/>
            <friction>
              <torsional>
                <ode/>
              </torsional>
              <ode/>
            </friction>
          </surface>
        </collision>
        <self_collide>0</self_collide>
        <enable_wind>0</enable_wind>
        <kinematic>0</kinematic>
      </link>
      <link name='Wall_11'>
        <collision name='Wall_11_Collision'>
          <geometry>
            <box>
              <size>3 0.15 2.5</size>
            </box>
          </geometry>
          <pose>0 0 1.25 0 -0 0</pose>
          <max_contacts>10</max_contacts>
          <surface>
            <contact>
              <ode/>
            </contact>
            <bounce/>
            <friction>
              <torsional>
                <ode/>
              </torsional>
              <ode/>
            </friction>
          </surface>
        </collision>
        <visual name='Wall_11_Visual'>
          <pose>0 0 1.25 0 -0 0</pose>
          <geometry>
            <box>
              <size>3 0.15 2.5</size>
            </box>
          </geometry>
          <material>
            <script>
              <uri>file://media/materials/scripts/gazebo.material</uri>
              <name>Gazebo/Grey</name>
            </script>
            <ambient>0.435294 0.796078 0.67451 1</ambient>
          </material>
          <meta>
            <layer>0</layer>
          </meta>
        </visual>
        <pose>-2.97842 -0.646354 0 0 -0 -1.5708</pose>
        <self_collide>0</self_collide>
        <enable_wind>0</enable_wind>
        <kinematic>0</kinematic>
      </link>
      <link name='Wall_2'>
        <pose>6.8 0 0 0 -0 1.5708</pose>
        <visual name='Wall_2_Visual_0'>
          <pose>-0.63892 0 1.25 0 -0 0</pose>
          <geometry>
            <box>
              <size>6.72216 0.15 2.5</size>
            </box>
          </geometry>
          <material>
            <script>
              <uri>file://media/materials/scripts/gazebo.material</uri>
              <name>Gazebo/Wood</name>
            </script>
            <ambient>1 1 1 1</ambient>
          </material>
          <meta>
            <layer>0</layer>
          </meta>
        </visual>
        <collision name='Wall_2_Collision_0'>
          <geometry>
            <box>
              <size>6.72216 0.15 2.5</size>
            </box>
          </geometry>
          <pose>-0.63892 0 1.25 0 -0 0</pose>
          <max_contacts>10</max_contacts>
          <surface>
            <contact>
              <ode/>
            </contact>
            <bounce/>
            <friction>
              <torsional>
                <ode/>
              </torsional>
              <ode/>
            </friction>
          </surface>
        </collision>
        <visual name='Wall_2_Visual_1'>
          <pose>3.81108 0 1.25 0 -0 0</pose>
          <geometry>
            <box>
              <size>0.377839 0.15 2.5</size>
            </box>
          </geometry>
          <material>
            <script>
              <uri>file://media/materials/scripts/gazebo.material</uri>
              <name>Gazebo/Wood</name>
            </script>
            <ambient>1 1 1 1</ambient>
          </material>
          <meta>
            <layer>0</layer>
          </meta>
        </visual>
        <collision name='Wall_2_Collision_1'>
          <geometry>
            <box>
              <size>0.377839 0.15 2.5</size>
            </box>
          </geometry>
          <pose>3.81108 0 1.25 0 -0 0</pose>
          <max_contacts>10</max_contacts>
          <surface>
            <contact>
              <ode/>
            </contact>
            <bounce/>
            <friction>
              <torsional>
                <ode/>
              </torsional>
              <ode/>
            </friction>
          </surface>
        </collision>
        <visual name='Wall_2_Visual_2'>
          <pose>3.17216 0 2.25 0 -0 0</pose>
          <geometry>
            <box>
              <size>0.9 0.15 0.5</size>
            </box>
          </geometry>
          <material>
            <script>
              <uri>file://media/materials/scripts/gazebo.material</uri>
              <name>Gazebo/Wood</name>
            </script>
            <ambient>1 1 1 1</ambient>
          </material>
          <meta>
            <layer>0</layer>
          </meta>
        </visual>
        <collision name='Wall_2_Collision_2'>
          <geometry>
            <box>
              <size>0.9 0.15 0.5</size>
            </box>
          </geometry>
          <pose>3.17216 0 2.25 0 -0 0</pose>
          <max_contacts>10</max_contacts>
          <surface>
            <contact>
              <ode/>
            </contact>
            <bounce/>
            <friction>
              <torsional>
                <ode/>
              </torsional>
              <ode/>
            </friction>
          </surface>
        </collision>
        <self_collide>0</self_collide>
        <enable_wind>0</enable_wind>
        <kinematic>0</kinematic>
      </link>
      <link name='Wall_3'>
        <collision name='Wall_3_Collision'>
          <geometry>
            <box>
              <size>13.75 0.15 2.5</size>
            </box>
          </geometry>
          <pose>0 0 1.25 0 -0 0</pose>
          <max_contacts>10</max_contacts>
          <surface>
            <contact>
              <ode/>
            </contact>
            <bounce/>
            <friction>
              <torsional>
                <ode/>
              </torsional>
              <ode/>
            </friction>
          </surface>
        </collision>
        <visual name='Wall_3_Visual'>
          <pose>0 0 1.25 0 -0 0</pose>
          <geometry>
            <box>
              <size>13.75 0.15 2.5</size>
            </box>
          </geometry>
          <material>
            <script>
              <uri>file://media/materials/scripts/gazebo.material</uri>
              <name>Gazebo/Wood</name>
            </script>
            <ambient>1 1 1 1</ambient>
          </material>
          <meta>
            <layer>0</layer>
          </meta>
        </visual>
        <pose>0 3.925 0 0 -0 3.14159</pose>
        <self_collide>0</self_collide>
        <enable_wind>0</enable_wind>
        <kinematic>0</kinematic>
      </link>
      <link name='Wall_6'>
        <pose>-6.8 0 0 0 -0 -1.5708</pose>
        <visual name='Wall_6_Visual_0'>
          <pose>-3.40392 0 1.25 0 -0 0</pose>
          <geometry>
            <box>
              <size>1.19216 0.15 2.5</size>
            </box>
          </geometry>
          <material>
            <script>
              <uri>file://media/materials/scripts/gazebo.material</uri>
              <name>Gazebo/Wood</name>
            </script>
            <ambient>1 1 1 1</ambient>
          </material>
          <meta>
            <layer>0</layer>
          </meta>
        </visual>
        <collision name='Wall_6_Collision_0'>
          <geometry>
            <box>
              <size>1.19216 0.15 2.5</size>
            </box>
          </geometry>
          <pose>-3.40392 0 1.25 0 -0 0</pose>
          <max_contacts>10</max_contacts>
          <surface>
            <contact>
              <ode/>
            </contact>
            <bounce/>
            <friction>
              <torsional>
                <ode/>
              </torsional>
              <ode/>
            </friction>
          </surface>
        </collision>
        <visual name='Wall_6_Visual_1'>
          <pose>0.596078 0 0.25 0 -0 0</pose>
          <geometry>
            <box>
              <size>6.80785 0.15 0.5</size>
            </box>
          </geometry>
          <material>
            <script>
              <uri>file://media/materials/scripts/gazebo.material</uri>
              <name>Gazebo/Wood</name>
            </script>
            <ambient>1 1 1 1</ambient>
          </material>
          <meta>
            <layer>0</layer>
          </meta>
        </visual>
        <collision name='Wall_6_Collision_1'>
          <geometry>
            <box>
              <size>6.80785 0.15 0.5</size>
            </box>
          </geometry>
          <pose>0.596078 0 0.25 0 -0 0</pose>
          <max_contacts>10</max_contacts>
          <surface>
            <contact>
              <ode/>
            </contact>
            <bounce/>
            <friction>
              <torsional>
                <ode/>
              </torsional>
              <ode/>
            </friction>
          </surface>
        </collision>
        <visual name='Wall_6_Visual_2'>
          <pose>0.996078 0 1.5 0 -0 0</pose>
          <geometry>
            <box>
              <size>6.00784 0.15 2</size>
            </box>
          </geometry>
          <material>
            <script>
              <uri>file://media/materials/scripts/gazebo.material</uri>
              <name>Gazebo/Wood</name>
            </script>
            <ambient>1 1 1 1</ambient>
          </material>
          <meta>
            <layer>0</layer>
          </meta>
        </visual>
        <collision name='Wall_6_Collision_2'>
          <geometry>
            <box>
              <size>6.00784 0.15 2</size>
            </box>
          </geometry>
          <pose>0.996078 0 1.5 0 -0 0</pose>
          <max_contacts>10</max_contacts>
          <surface>
            <contact>
              <ode/>
            </contact>
            <bounce/>
            <friction>
              <torsional>
                <ode/>
              </torsional>
              <ode/>
            </friction>
          </surface>
        </collision>
        <visual name='Wall_6_Visual_3'>
          <pose>-2.40785 0 1.9 0 -0 0</pose>
          <geometry>
            <box>
              <size>0.8 0.15 1.2</size>
            </box>
          </geometry>
          <material>
            <script>
              <uri>file://media/materials/scripts/gazebo.material</uri>
              <name>Gazebo/Wood</name>
            </script>
            <ambient>1 1 1 1</ambient>
          </material>
          <meta>
            <layer>0</layer>
          </meta>
        </visual>
        <collision name='Wall_6_Collision_3'>
          <geometry>
            <box>
              <size>0.8 0.15 1.2</size>
            </box>
          </geometry>
          <pose>-2.40785 0 1.9 0 -0 0</pose>
          <max_contacts>10</max_contacts>
          <surface>
            <contact>
              <ode/>
            </contact>
            <bounce/>
            <friction>
              <torsional>
                <ode/>
              </torsional>
              <ode/>
            </friction>
          </surface>
        </collision>
        <self_collide>0</self_collide>
        <enable_wind>0</enable_wind>
        <kinematic>0</kinematic>
      </link>
      <link name='Wall_8'>
        <pose>-0.987178 2.36636 0 0 -0 -1.5708</pose>
        <visual name='Wall_8_Visual_0'>
          <pose>-1.28955 0 1.25 0 -0 0</pose>
          <geometry>
            <box>
              <size>0.670906 0.15 2.5</size>
            </box>
          </geometry>
          <material>
            <script>
              <uri>file://media/materials/scripts/gazebo.material</uri>
              <name>Gazebo/Grey</name>
            </script>
            <ambient>0.435294 0.796078 0.67451 1</ambient>
          </material>
          <meta>
            <layer>0</layer>
          </meta>
        </visual>
        <collision name='Wall_8_Collision_0'>
          <geometry>
            <box>
              <size>0.670906 0.15 2.5</size>
            </box>
          </geometry>
          <pose>-1.28955 0 1.25 0 -0 0</pose>
          <max_contacts>10</max_contacts>
          <surface>
            <contact>
              <ode/>
            </contact>
            <bounce/>
            <friction>
              <torsional>
                <ode/>
              </torsional>
              <ode/>
            </friction>
          </surface>
        </collision>
        <visual name='Wall_8_Visual_1'>
          <pose>0.785453 0 1.25 0 -0 0</pose>
          <geometry>
            <box>
              <size>1.67909 0.15 2.5</size>
            </box>
          </geometry>
          <material>
            <script>
              <uri>file://media/materials/scripts/gazebo.material</uri>
              <name>Gazebo/Grey</name>
            </script>
            <ambient>0.435294 0.796078 0.67451 1</ambient>
          </material>
          <meta>
            <layer>0</layer>
          </meta>
        </visual>
        <collision name='Wall_8_Collision_1'>
          <geometry>
            <box>
              <size>1.67909 0.15 2.5</size>
            </box>
          </geometry>
          <pose>0.785453 0 1.25 0 -0 0</pose>
          <max_contacts>10</max_contacts>
          <surface>
            <contact>
              <ode/>
            </contact>
            <bounce/>
            <friction>
              <torsional>
                <ode/>
              </torsional>
              <ode/>
            </friction>
          </surface>
        </collision>
        <visual name='Wall_8_Visual_2'>
          <pose>-0.504094 0 2.25 0 -0 0</pose>
          <geometry>
            <box>
              <size>0.9 0.15 0.5</size>
            </box>
          </geometry>
          <material>
            <script>
              <uri>file://media/materials/scripts/gazebo.material</uri>
              <name>Gazebo/Grey</name>
            </script>
            <ambient>0.435294 0.796078 0.67451 1</ambient>
          </material>
          <meta>
            <layer>0</layer>
          </meta>
        </visual>
        <collision name='Wall_8_Collision_2'>
          <geometry>
            <box>
              <size>0.9 0.15 0.5</size>
            </box>
          </geometry>
          <pose>-0.504094 0 2.25 0 -0 0</pose>
          <max_contacts>10</max_contacts>
          <surface>
            <contact>
              <ode/>
            </contact>
            <bounce/>
            <friction>
              <torsional>
                <ode/>
              </torsional>
              <ode/>
            </friction>
          </surface>
        </collision>
        <self_collide>0</self_collide>
        <enable_wind>0</enable_wind>
        <kinematic>0</kinematic>
      </link>
      <link name='Wall_9'>
        <collision name='Wall_9_Collision'>
          <geometry>
            <box>
              <size>4 0.15 2.5</size>
            </box>
          </geometry>
          <pose>0 0 1.25 0 -0 0</pose>
          <max_contacts>10</max_contacts>
          <surface>
            <contact>
              <ode/>
            </contact>
            <bounce/>
            <friction>
              <torsional>
                <ode/>
              </torsional>
              <ode/>
            </friction>
          </surface>
        </collision>
        <visual name='Wall_9_Visual'>
          <pose>0 0 1.25 0 -0 0</pose>
          <geometry>
            <box>
              <size>4 0.15 2.5</size>
            </box>
          </geometry>
          <material>
            <script>
              <uri>file://media/materials/scripts/gazebo.material</uri>
              <name>Gazebo/Grey</name>
            </script>
            <ambient>0.435294 0.796078 0.67451 1</ambient>
          </material>
          <meta>
            <layer>0</layer>
          </meta>
        </visual>
        <pose>-2.91218 0.816363 0 0 -0 3.14159</pose>
        <self_collide>0</self_collide>
        <enable_wind>0</enable_wind>
        <kinematic>0</kinematic>
      </link>
      <static>1</static>
    </model>
    <gui fullscreen='0'>
      <camera name='user_camera'>
        <pose>7.84514 -1.83459 6.50548 0 0.849796 3.0202</pose>
        <view_controller>orbit</view_controller>
        <projection_type>perspective</projection_type>
      </camera>
    </gui>
    <model name='my_ball_0'>
      <link name='link_0'>
        <inertial>
          <mass>1</mass>
          <inertia>
            <ixx>0.1</ixx>
            <ixy>0</ixy>
            <ixz>0</ixz>
            <iyy>0.1</iyy>
            <iyz>0</iyz>
            <izz>0.1</izz>
          </inertia>
          <pose>0 0 0 0 -0 0</pose>
        </inertial>
        <pose>0 0 0 0 -0 0</pose>
        <gravity>1</gravity>
        <self_collide>0</self_collide>
        <kinematic>0</kinematic>
        <enable_wind>0</enable_wind>
        <visual name='visual'>
          <pose>0 0 0 0 -0 0</pose>
          <geometry>
            <sphere>
              <radius>0.1</radius>
            </sphere>
          </geometry>
          <material>
            <lighting>1</lighting>
            <script>
              <uri>file://media/materials/scripts/gazebo.material</uri>
              <name>Gazebo/Grey</name>
            </script>
            <shader type='pixel'>
              <normal_map>__default__</normal_map>
            </shader>
            <ambient>1 1 1 1</ambient>
            <diffuse>1 1 1 1</diffuse>
            <specular>1 1 1 1</specular>
            <emissive>1 1 1 1</emissive>
          </material>
          <transparency>0</transparency>
          <cast_shadows>1</cast_shadows>
        </visual>
        <collision name='collision'>
          <laser_retro>0</laser_retro>
          <max_contacts>10</max_contacts>
          <pose>0 0 0 0 -0 0</pose>
          <geometry>
            <sphere>
              <radius>0.1</radius>
            </sphere>
          </geometry>
          <surface>
            <friction>
              <ode>
                <mu>1</mu>
                <mu2>1</mu2>
                <fdir1>0 0 0</fdir1>
                <slip1>0</slip1>
                <slip2>0</slip2>
              </ode>
              <torsional>
                <coefficient>1</coefficient>
                <patch_radius>0</patch_radius>
                <surface_radius>0</surface_radius>
                <use_patch_radius>1</use_patch_radius>
                <ode>
                  <slip>0</slip>
                </ode>
              </torsional>
            </friction>
            <bounce>
              <restitution_coefficient>0</restitution_coefficient>
              <threshold>1e+06</threshold>
            </bounce>
            <contact>
              <collide_without_contact>0</collide_without_contact>
              <collide_without_contact_bitmask>1</collide_without_contact_bitmask>
              <collide_bitmask>1</collide_bitmask>
              <ode>
                <soft_cfm>0</soft_cfm>
                <soft_erp>0.2</soft_erp>
                <kp>1e+13</kp>
                <kd>1</kd>
                <max_vel>0.01</max_vel>
                <min_depth>0</min_depth>
              </ode>
              <bullet>
                <split_impulse>1</split_impulse>
                <split_impulse_penetration_threshold>-0.01</split_impulse_penetration_threshold>
                <soft_cfm>0</soft_cfm>
                <soft_erp>0.2</soft_erp>
                <kp>1e+13</kp>
                <kd>1</kd>
              </bullet>
            </contact>
          </surface>
        </collision>
      </link>
      <static>0</static>
      <allow_auto_disable>1</allow_auto_disable>
      <pose>2.47418 -3.50185 0 0 -0 0</pose>
    </model>
  </world>
</sdf>
